Workbook

Sheet Calculator
B2: FOREX & PROP-FIRM TRADE CALCULATOR
B3: Set your inputs once, then for each trade just type the green Entry Price cell.
B5: 1 - SETTINGS (edit once)
B6: Account Balance ($) | C6: 2488.76 | D6: <- your current balance used for risk sizing
B7: Risk % per Trade | C7: 0.01 | D7: <- e.g. 1.00% (keep <= 1-2%)
B8: Instrument | C8: XAUUSD | D8: <- dropdown: EURUSD / GBPUSD / XAUUSD
B9: Direction | C9: BUY | D9: <- dropdown: BUY / SELL
B10: Stop-Loss Distance (pips) | C10: 25 | D10: <- defines your risk distance
B11: Risk : Reward (1 : x) | C11: 2 | D11: <- 1, 1.5, 2, 3, 4, 5 or custom
B13: 2 - ENTRY (the only thing you change per trade)
B14: Entry Price | C14: 2350 | D14: <- TYPE YOUR ENTRY HERE
B16: 3 - INSTRUMENT DATA (auto)
B17: Pip Size | C17: =VLOOKUP($C$8,Instruments!$A$2:$F$4,2,FALSE)
B18: Pip Value per Lot ($) | C18: =VLOOKUP($C$8,Instruments!$A$2:$F$4,3,FALSE)
B19: Price Decimals | C19: =VLOOKUP($C$8,Instruments!$A$2:$F$4,5,FALSE)
B21: 4 - RESULTS (auto-calculated)
B22: Stop-Loss Price | C22: =IF($C$9="BUY",$C$14-$C$10*$C$17,$C$14+$C$10*$C$17)
B23: Take-Profit Price | C23: =IF($C$9="BUY",$C$14+$C$10*$C$17*$C$11,$C$14-$C$10*$C$17*$C$11)
B24: Stop Distance (price) | C24: =$C$10*$C$17
B25: Reward Distance (pips) | C25: =$C$10*$C$11
B26: Dollar Risk ($) | C26: =$C$6*$C$7
B27: Recommended Lot (raw) | C27: =IF($C$10*$C$18=0,0,$C$26/($C$10*$C$18))
B28: Recommended Lot Size | C28: =ROUND($C$27,2)
B29: Actual Risk at Lot ($) | C29: =$C$28*$C$10*$C$18
B30: Potential Profit ($) | C30: =$C$29*$C$11
B31: Risk : Reward | C31: ="1 : "&TEXT($C$11,"0.##")
B33: 5 - PROP-FIRM RULE CHECK (optional)
B34: Starting Balance ($) | C34: 2500
B35: Current Equity ($) | C35: 2488.76
B36: Daily Drawdown Limit (%) | C36: 0.03
B37: Max Drawdown Limit (%) | C37: 0.06
B38: Profit Target (%) | C38: 0.03
B39: Remaining Daily Drawdown ($) | C39: =MAX(0,$C$35-($C$6-$C$34*$C$36))
B40: Remaining Max Drawdown ($) | C40: =MAX(0,$C$35-($C$34*(1-$C$37)))
B41: Losing Trades left (Daily) | C41: =IF($C$29<=0,0,FLOOR($C$39/$C$29,1))
B42: Losing Trades left (Max) | C42: =IF($C$29<=0,0,FLOOR($C$40/$C$29,1))
B43: Losing Trades remaining | C43: =MIN($C$41,$C$42)
B44: Profit Target ($) | C44: =$C$34*$C$38
B45: Amount to Reach Target ($) | C45: =MAX(0,($C$34+$C$44)-$C$6)
B46: Winning Trades to Pass | C46: =IF($C$30<=0,"-",ROUNDUP($C$45/$C$30,0))
...

Sheet Trade Planner
B2: TRADE PLANNER - enter Direction + Entry Price on each row
B4: SETTINGS
B5: Account Balance ($) | C5: 2488.76 | E5: Pip Size: | F5: =VLOOKUP($C$7,Instruments!$A$2:$F$4,2,FALSE)
B6: Risk % per Trade | C6: 0.01 | E6: Pip Value / Lot: | F6: =VLOOKUP($C$7,Instruments!$A$2:$F$4,3,FALSE)
B7: Instrument | C7: XAUUSD | E7: Dollar Risk / Trade: | F7: =$C$5*$C$6
B8: Stop-Loss (pips) | C8: 25
B9: Risk : Reward (1 : x) | C9: 2
B11: # | C11: Direction | D11: Entry Price | E11: Stop-Loss | F11: Take-Profit | G11: Dollar Risk | H11: Lot Size | I11: Potential Profit | J11: Notes
B12: 1 | C12: BUY | D12: 2350 | E12: =IF($D12="","",IF($C12="SELL",$D12+$C$8*$F$5,$D12-$C$8*$F$5)) | F12: =IF($D12="","",IF($C12="SELL",$D12-$C$8*$F$5*$C$9,$D12+$C$8*$F$5*$C$9)) | G12: =IF($D12="","",$F$7) | H12: =IF($D12="","",ROUND($F$7/($C$8*$F$6),2)) | I12: =IF($D12="","",$F$7*$C$9)
B13: 2 | C13: BUY | E13: =IF($D13="","",IF($C13="SELL",$D13+$C$8*$F$5,$D13-$C$8*$F$5)) | F13: =IF($D13="","",IF($C13="SELL",$D13-$C$8*$F$5*$C$9,$D13+$C$8*$F$5*$C$9)) | G13: =IF($D13="","",$F$7) | H13: =IF($D13="","",ROUND($F$7/($C$8*$F$6),2)) | I13: =IF($D13="","",$F$7*$C$9)
B14: 3 | C14: BUY | E14: =IF($D14="","",IF($C14="SELL",$D14+$C$8*$F$5,$D14-$C$8*$F$5)) | F14: =IF($D14="","",IF($C14="SELL",$D14-$C$8*$F$5*$C$9,$D14+$C$8*$F$5*$C$9)) | G14: =IF($D14="","",$F$7) | H14: =IF($D14="","",ROUND($F$7/($C$8*$F$6),2)) | I14: =IF($D14="","",$F$7*$C$9)
B15: 4 | C15: BUY | E15: =IF($D15="","",IF($C15="SELL",$D15+$C$8*$F$5,$D15-$C$8*$F$5)) | F15: =IF($D15="","",IF($C15="SELL",$D15-$C$8*$F$5*$C$9,$D15+$C$8*$F$5*$C$9)) | G15: =IF($D15="","",$F$7) | H15: =IF($D15="","",ROUND($F$7/($C$8*$F$6),2)) | I15: =IF($D15="","",$F$7*$C$9)
B16: 5 | C16: BUY | E16: =IF($D16="","",IF($C16="SELL",$D16+$C$8*$F$5,$D16-$C$8*$F$5)) | F16: =IF($D16="","",IF($C16="SELL",$D16-$C$8*$F$5*$C$9,$D16+$C$8*$F$5*$C$9)) | G16: =IF($D16="","",$F$7) | H16: =IF($D16="","",ROUND($F$7/($C$8*$F$6),2)) | I16: =IF($D16="","",$F$7*$C$9)
B17: 6 | C17: BUY | E17: =IF($D17="","",IF($C17="SELL",$D17+$C$8*$F$5,$D17-$C$8*$F$5)) | F17: =IF($D17="","",IF($C17="SELL",$D17-$C$8*$F$5*$C$9,$D17+$C$8*$F$5*$C$9)) | G17: =IF($D17="","",$F$7) | H17: =IF($D17="","",ROUND($F$7/($C$8*$F$6),2)) | I17: =IF($D17="","",$F$7*$C$9)
B18: 7 | C18: BUY | E18: =IF($D18="","",IF($C18="SELL",$D18+$C$8*$F$5,$D18-$C$8*$F$5)) | F18: =IF($D18="","",IF($C18="SELL",$D18-$C$8*$F$5*$C$9,$D18+$C$8*$F$5*$C$9)) | G18: =IF($D18="","",$F$7) | H18: =IF($D18="","",ROUND($F$7/($C$8*$F$6),2)) | I18: =IF($D18="","",$F$7*$C$9)
B19: 8 | C19: BUY | E19: =IF($D19="","",IF($C19="SELL",$D19+$C$8*$F$5,$D19-$C$8*$F$5)) | F19: =IF($D19="","",IF($C19="SELL",$D19-$C$8*$F$5*$C$9,$D19+$C$8*$F$5*$C$9)) | G19: =IF($D19="","",$F$7) | H19: =IF($D19="","",ROUND($F$7/($C$8*$F$6),2)) | I19: =IF($D19="","",$F$7*$C$9)
B20: 9 | C20: BUY | E20: =IF($D20="","",IF($C20="SELL",$D20+$C$8*$F$5,$D20-$C$8*$F$5)) | F20: =IF($D20="","",IF($C20="SELL",$D20-$C$8*$F$5*$C$9,$D20+$C$8*$F$5*$C$9)) | G20: =IF($D20="","",$F$7) | H20: =IF($D20="","",ROUND($F$7/($C$8*$F$6),2)) | I20: =IF($D20="","",$F$7*$C$9)
B21: 10 | C21: BUY | E21: =IF($D21="","",IF($C21="SELL",$D21+$C$8*$F$5,$D21-$C$8*$F$5)) | F21: =IF($D21="","",IF($C21="SELL",$D21-$C$8*$F$5*$C$9,$D21+$C$8*$F$5*$C$9)) | G21: =IF($D21="","",$F$7) | H21: =IF($D21="","",ROUND($F$7/($C$8*$F$6),2)) | I21: =IF($D21="","",$F$7*$C$9)
B22: 11 | C22: BUY | E22: =IF($D22="","",IF($C22="SELL",$D22+$C$8*$F$5,$D22-$C$8*$F$5)) | F22: =IF($D22="","",IF($C22="SELL",$D22-$C$8*$F$5*$C$9,$D22+$C$8*$F$5*$C$9)) | G22: =IF($D22="","",$F$7) | H22: =IF($D22="","",ROUND($F$7/($C$8*$F$6),2)) | I22: =IF($D22="","",$F$7*$C$9)
B23: 12 | C23: BUY | E23: =IF($D23="","",IF($C23="SELL",$D23+$C$8*$F$5,$D23-$C$8*$F$5)) | F23: =IF($D23="","",IF($C23="SELL",$D23-$C$8*$F$5*$C$9,$D23+$C$8*$F$5*$C$9)) | G23: =IF($D23="","",$F$7) | H23: =IF($D23="","",ROUND($F$7/($C$8*$F$6),2)) | I23: =IF($D23="","",$F$7*$C$9)
B24: 13 | C24: BUY | E24: =IF($D24="","",IF($C24="SELL",$D24+$C$8*$F$5,$D24-$C$8*$F$5)) | F24: =IF($D24="","",IF($C24="SELL",$D24-$C$8*$F$5*$C$9,$D24+$C$8*$F$5*$C$9)) | G24: =IF($D24="","",$F$7) | H24: =IF($D24="","",ROUND($F$7/($C$8*$F$6),2)) | I24: =IF($D24="","",$F$7*$C$9)
... B26: 15 | C26: BUY | E26: =IF($D26="","",IF($C26="SELL",$D26+$C$8*$F$5,$D26-$C$8*$F$5)) | F26: =IF($D26="","",IF($C26="SELL",$D26-$C$8*$F$5*$C$9,$D26+$C$8*$F$5*$C$9)) | G26: =IF($D26="","",$F$7) | H26: =IF($D26="","",ROUND($F$7/($C$8*$F$6),2)) | I26: =IF($D26="","",$F$7*$C$9)
B28: Tip: copy a row down to add more trades. Change the SETTINGS block to re-size every row at once.

Sheet Instruments
A1: Symbol | B1: Pip Size | C1: Pip Value / Lot ($) | D1: Contract Size | E1: Price Decimals | F1: Reference Price
A2: EURUSD | B2: 0.0001 | C2: 10 | D2: 100000 | E2: 5 | F2: 1.085
A3: GBPUSD | B3: 0.0001 | C3: 10 | D3: 100000 | E3: 5 | F3: 1.27
A4: XAUUSD | B4: 0.1 | C4: 10 | D4: 100 | E4: 2 | F4: 2350
A6: Note: For these USD-quoted pairs, 1 pip per standard lot = $10. Gold (XAUUSD) assumes a 100-oz contract where a $0.10 move = $10/lot. Adjust these values to match your broker if needed.
